<?xml version="1.0" ?>
<robot name="robotic_arm" xmlns:xacro="http://www.ros.org/wiki/xacro">

<xacro:include filename="$(find robotic_arm_description)/urdf/materials.xacro" />
<xacro:include filename="$(find robotic_arm_description)/urdf/robotic_arm.trans" />
<xacro:include filename="$(find robotic_arm_description)/urdf/robotic_arm.gazebo" />
<link name="base_link">
  <inertial>
    <origin xyz="-0.012591017413675576 -0.02625452248023994 0.01882692231493027" rpy="0 0 0"/>
    <mass value="0.15109268796453854"/>
    <inertia ixx="0.000155" iyy="0.000175" izz="0.000246" ixy="0.0" iyz="-1e-06" ixz="1.4e-05"/>
  </inertial>
  <visual>
    <origin xyz="0 0 0" rpy="0 0 0"/>
    <geometry>
      <mesh filename="package://robotic_arm_description/meshes/base_link.stl" scale="0.001 0.001 0.001"/>
    </geometry>
    <material name="silver"/>
  </visual>
  <collision>
    <origin xyz="0 0 0" rpy="0 0 0"/>
    <geometry>
      <mesh filename="package://robotic_arm_description/meshes/base_link.stl" scale="0.001 0.001 0.001"/>
    </geometry>
  </collision>
</link>

<link name="WAIST_1">
  <inertial>
    <origin xyz="0.0022441628498335066 0.007590344465981981 0.01877031829177992" rpy="0 0 0"/>
    <mass value="0.07662775042719305"/>
    <inertia ixx="5.2e-05" iyy="6.6e-05" izz="6e-05" ixy="-2e-06" iyz="-7e-06" ixz="-7e-06"/>
  </inertial>
  <visual>
    <origin xyz="0.019548 0.026486 -0.056" rpy="0 0 0"/>
    <geometry>
      <mesh filename="package://robotic_arm_description/meshes/WAIST_1.stl" scale="0.001 0.001 0.001"/>
    </geometry>
    <material name="silver"/>
  </visual>
  <collision>
    <origin xyz="0.019548 0.026486 -0.056" rpy="0 0 0"/>
    <geometry>
      <mesh filename="package://robotic_arm_description/meshes/WAIST_1.stl" scale="0.001 0.001 0.001"/>
    </geometry>
  </collision>
</link>

<link name="ARM_1_1">
  <inertial>
    <origin xyz="-0.0009032606766832757 -0.008109648473576453 0.05503482652373645" rpy="0 0 0"/>
    <mass value="0.0632866707153552"/>
    <inertia ixx="0.000123" iyy="0.000127" izz="9e-06" ixy="0.0" iyz="1e-06" ixz="-4e-06"/>
  </inertial>
  <visual>
    <origin xyz="0.005629 0.022537 -0.096277" rpy="0 0 0"/>
    <geometry>
      <mesh filename="package://robotic_arm_description/meshes/ARM_1_1.stl" scale="0.001 0.001 0.001"/>
    </geometry>
    <material name="silver"/>
  </visual>
  <collision>
    <origin xyz="0.005629 0.022537 -0.096277" rpy="0 0 0"/>
    <geometry>
      <mesh filename="package://robotic_arm_description/meshes/ARM_1_1.stl" scale="0.001 0.001 0.001"/>
    </geometry>
  </collision>
</link>

<link name="ARM_2_1">
  <inertial>
    <origin xyz="3.634368510697407e-05 0.009778981953459059 0.03809627169057139" rpy="0 0 0"/>
    <mass value="0.06035597163948405"/>
    <inertia ixx="6.7e-05" iyy="7.1e-05" izz="1.2e-05" ixy="-0.0" iyz="-1e-06" ixz="-0.0"/>
  </inertial>
  <visual>
    <origin xyz="0.005629 0.022537 -0.216277" rpy="0 0 0"/>
    <geometry>
      <mesh filename="package://robotic_arm_description/meshes/ARM_2_1.stl" scale="0.001 0.001 0.001"/>
    </geometry>
    <material name="silver"/>
  </visual>
  <collision>
    <origin xyz="0.005629 0.022537 -0.216277" rpy="0 0 0"/>
    <geometry>
      <mesh filename="package://robotic_arm_description/meshes/ARM_2_1.stl" scale="0.001 0.001 0.001"/>
    </geometry>
  </collision>
</link>

<link name="ARM_3_1">
  <inertial>
    <origin xyz="0.005059774534390374 0.005785393240177364 0.018265223108916318" rpy="0 0 0"/>
    <mass value="0.019243658186513544"/>
    <inertia ixx="5e-06" iyy="6e-06" izz="3e-06" ixy="0.0" iyz="-1e-06" ixz="0.0"/>
  </inertial>
  <visual>
    <origin xyz="0.000329 0.013037 -0.306027" rpy="0 0 0"/>
    <geometry>
      <mesh filename="package://robotic_arm_description/meshes/ARM_3_1.stl" scale="0.001 0.001 0.001"/>
    </geometry>
    <material name="silver"/>
  </visual>
  <collision>
    <origin xyz="0.000329 0.013037 -0.306027" rpy="0 0 0"/>
    <geometry>
      <mesh filename="package://robotic_arm_description/meshes/ARM_3_1.stl" scale="0.001 0.001 0.001"/>
    </geometry>
  </collision>
</link>

<link name="Gripper_base_v1_1">
  <inertial>
    <origin xyz="-0.0037420101480981063 0.0069768374118510095 0.023968262461229795" rpy="0 0 0"/>
    <mass value="0.016664690973765797"/>
    <inertia ixx="9e-06" iyy="8e-06" izz="3e-06" ixy="0.0" iyz="-2e-06" ixz="1e-06"/>
  </inertial>
  <visual>
    <origin xyz="-0.004671 -0.002963 -0.334027" rpy="0 0 0"/>
    <geometry>
      <mesh filename="package://robotic_arm_description/meshes/Gripper_base_v1_1.stl" scale="0.001 0.001 0.001"/>
    </geometry>
    <material name="silver"/>
  </visual>
  <collision>
    <origin xyz="-0.004671 -0.002963 -0.334027" rpy="0 0 0"/>
    <geometry>
      <mesh filename="package://robotic_arm_description/meshes/Gripper_base_v1_1.stl" scale="0.001 0.001 0.001"/>
    </geometry>
  </collision>
</link>

<link name="gear2_v1_1">
  <inertial>
    <origin xyz="-0.0015298699434045599 0.002079903777759018 0.0054590376304928245" rpy="0 0 0"/>
    <mass value="0.0027198112495044778"/>
    <inertia ixx="0.0" iyy="0.0" izz="0.0" ixy="-0.0" iyz="-0.0" ixz="-0.0"/>
  </inertial>
  <visual>
    <origin xyz="0.005964 -0.025863 -0.373102" rpy="0 0 0"/>
    <geometry>
      <mesh filename="package://robotic_arm_description/meshes/gear2_v1_1.stl" scale="0.001 0.001 0.001"/>
    </geometry>
    <material name="silver"/>
  </visual>
  <collision>
    <origin xyz="0.005964 -0.025863 -0.373102" rpy="0 0 0"/>
    <geometry>
      <mesh filename="package://robotic_arm_description/meshes/gear2_v1_1.stl" scale="0.001 0.001 0.001"/>
    </geometry>
  </collision>
</link>

<link name="gear1_v1_1">
  <inertial>
    <origin xyz="-0.0015382545410094145 -0.0020873383753474434 0.0053632012413317165" rpy="0 0 0"/>
    <mass value="0.0028001100817075224"/>
    <inertia ixx="0.0" iyy="0.0" izz="0.0" ixy="0.0" iyz="0.0" ixz="-0.0"/>
  </inertial>
  <visual>
    <origin xyz="0.005964 0.001037 -0.373102" rpy="0 0 0"/>
    <geometry>
      <mesh filename="package://robotic_arm_description/meshes/gear1_v1_1.stl" scale="0.001 0.001 0.001"/>
    </geometry>
    <material name="silver"/>
  </visual>
  <collision>
    <origin xyz="0.005964 0.001037 -0.373102" rpy="0 0 0"/>
    <geometry>
      <mesh filename="package://robotic_arm_description/meshes/gear1_v1_1.stl" scale="0.001 0.001 0.001"/>
    </geometry>
  </collision>
</link>

<link name="Gripper_1_v1_1">
  <inertial>
    <origin xyz="0.006301934432243404 0.013438856005631494 0.023263497807370692" rpy="0 0 0"/>
    <mass value="0.0057212708857542725"/>
    <inertia ixx="2e-06" iyy="1e-06" izz="1e-06" ixy="-0.0" iyz="-1e-06" ixz="-0.0"/>
  </inertial>
  <visual>
    <origin xyz="0.003587 -0.040062 -0.400274" rpy="0 0 0"/>
    <geometry>
      <mesh filename="package://robotic_arm_description/meshes/Gripper_1_v1_1.stl" scale="0.001 0.001 0.001"/>
    </geometry>
    <material name="silver"/>
  </visual>
  <collision>
    <origin xyz="0.003587 -0.040062 -0.400274" rpy="0 0 0"/>
    <geometry>
      <mesh filename="package://robotic_arm_description/meshes/Gripper_1_v1_1.stl" scale="0.001 0.001 0.001"/>
    </geometry>
  </collision>
</link>

<link name="Gripper_1_v1__1__1">
  <inertial>
    <origin xyz="0.006553144234267914 -0.005915445838265192 0.026144538460451006" rpy="0 0 0"/>
    <mass value="0.0057212708857542725"/>
    <inertia ixx="2e-06" iyy="2e-06" izz="0.0" ixy="0.0" iyz="0.0" ixz="-0.0"/>
  </inertial>
  <visual>
    <origin xyz="0.003597 0.015473 -0.40015" rpy="0 0 0"/>
    <geometry>
      <mesh filename="package://robotic_arm_description/meshes/Gripper_1_v1__1__1.stl" scale="0.001 0.001 0.001"/>
    </geometry>
    <material name="silver"/>
  </visual>
  <collision>
    <origin xyz="0.003597 0.015473 -0.40015" rpy="0 0 0"/>
    <geometry>
      <mesh filename="package://robotic_arm_description/meshes/Gripper_1_v1__1__1.stl" scale="0.001 0.001 0.001"/>
    </geometry>
  </collision>
</link>

<joint name="Rev1" type="continuous">
  <origin xyz="-0.019548 -0.026486 0.056" rpy="0 0 0"/>
  <parent link="base_link"/>
  <child link="WAIST_1"/>
  <axis xyz="0.0 -0.0 1.0"/>
</joint>

<joint name="Rev2" type="revolute">
  <origin xyz="0.013919 0.003949 0.040277" rpy="0 0 0"/>
  <parent link="WAIST_1"/>
  <child link="ARM_1_1"/>
  <axis xyz="0.0 -1.0 -0.0"/>
  <limit upper="1.658063" lower="-1.48353" effort="100" velocity="100"/>
</joint>

<joint name="Rev3" type="revolute">
  <origin xyz="0.0 0.0 0.12" rpy="0 0 0"/>
  <parent link="ARM_1_1"/>
  <child link="ARM_2_1"/>
  <axis xyz="-0.0 1.0 0.0"/>
  <limit upper="1.48353" lower="-1.22173" effort="100" velocity="100"/>
</joint>

<joint name="Rev4" type="continuous">
  <origin xyz="0.0053 0.0095 0.08975" rpy="0 0 0"/>
  <parent link="ARM_2_1"/>
  <child link="ARM_3_1"/>
  <axis xyz="-0.0 -0.0 1.0"/>
</joint>

<joint name="Rev30" type="revolute">
  <origin xyz="0.005 0.016 0.028" rpy="0 0 0"/>
  <parent link="ARM_3_1"/>
  <child link="Gripper_base_v1_1"/>
  <axis xyz="-0.0 1.0 0.0"/>
  <limit upper="1.832596" lower="-1.396263" effort="100" velocity="100"/>
</joint>

<joint name="Rev31" type="revolute">
  <origin xyz="-0.010635 0.0229 0.039075" rpy="0 0 0"/>
  <parent link="Gripper_base_v1_1"/>
  <child link="gear2_v1_1"/>
  <axis xyz="-0.996195 -0.0 0.087156"/>
  <limit upper="0.349066" lower="-0.349066" effort="100" velocity="100"/>
</joint>

<joint name="Rev32" type="revolute">
  <origin xyz="-0.010635 -0.004 0.039075" rpy="0 0 0"/>
  <parent link="Gripper_base_v1_1"/>
  <child link="gear1_v1_1"/>
  <axis xyz="-0.996195 -0.0 0.087156"/>
  <limit upper="0.349066" lower="-0.349066" effort="100" velocity="100"/>
</joint>

<joint name="Rigid36" type="fixed">
  <origin xyz="0.002377 0.014199 0.027172" rpy="0 0 0"/>
  <parent link="gear2_v1_1"/>
  <child link="Gripper_1_v1_1"/>
</joint>

<joint name="Rigid37" type="fixed">
  <origin xyz="0.002367 -0.014436 0.027048" rpy="0 0 0"/>
  <parent link="gear1_v1_1"/>
  <child link="Gripper_1_v1__1__1"/>
</joint>

</robot>
